2022-07-21 20:26:49,439 INFO    MainThread:1816151 [internal.py:wandb_internal():90] W&B internal server running at pid: 1816151, started at: 2022-07-21 20:26:49.439323
2022-07-21 20:26:49,441 INFO    WriterThread:1816151 [datastore.py:open_for_write():75] open: /home/dami/Inverse_GNN/wandb/run-20220721_202649-2qok1cwz/run-2qok1cwz.wandb
2022-07-21 20:26:49,443 DEBUG   SenderThread:1816151 [sender.py:send():236] send: header
2022-07-21 20:26:49,443 DEBUG   SenderThread:1816151 [sender.py:send():236] send: run
2022-07-21 20:27:19,145 DEBUG   HandlerThread:1816151 [handler.py:handle_request():140] handle_request: shutdown
2022-07-21 20:27:19,145 INFO    HandlerThread:1816151 [handler.py:finish():806] shutting down handler
2022-07-21 20:27:19,467 INFO    WriterThread:1816151 [datastore.py:close():279] close: /home/dami/Inverse_GNN/wandb/run-20220721_202649-2qok1cwz/run-2qok1cwz.wandb
2022-07-21 20:27:23,290 ERROR   SenderThread:1816151 [retry.py:__call__():132] Retry attempt failed:
Traceback (most recent call last):
  File "/home/dami/anaconda3/envs/fenics_d/lib/python3.10/site-packages/urllib3/connectionpool.py", line 449, in _make_request
    six.raise_from(e, None)
  File "<string>", line 3, in raise_from
  File "/home/dami/anaconda3/envs/fenics_d/lib/python3.10/site-packages/urllib3/connectionpool.py", line 444, in _make_request
    httplib_response = conn.getresponse()
  File "/home/dami/anaconda3/envs/fenics_d/lib/python3.10/http/client.py", line 1374, in getresponse
    response.begin()
  File "/home/dami/anaconda3/envs/fenics_d/lib/python3.10/http/client.py", line 318, in begin
    version, status, reason = self._read_status()
  File "/home/dami/anaconda3/envs/fenics_d/lib/python3.10/http/client.py", line 279, in _read_status
    line = str(self.fp.readline(_MAXLINE + 1), "iso-8859-1")
  File "/home/dami/anaconda3/envs/fenics_d/lib/python3.10/socket.py", line 705, in readinto
    return self._sock.recv_into(b)
  File "/home/dami/anaconda3/envs/fenics_d/lib/python3.10/ssl.py", line 1273, in recv_into
    return self.read(nbytes, buffer)
  File "/home/dami/anaconda3/envs/fenics_d/lib/python3.10/ssl.py", line 1129, in read
    return self._sslobj.read(len, buffer)
TimeoutError: The read operation timed out

During handling of the above exception, another exception occurred:

Traceback (most recent call last):
  File "/home/dami/anaconda3/envs/fenics_d/lib/python3.10/site-packages/requests/adapters.py", line 489, in send
    resp = conn.urlopen(
  File "/home/dami/anaconda3/envs/fenics_d/lib/python3.10/site-packages/urllib3/connectionpool.py", line 785, in urlopen
    retries = retries.increment(
  File "/home/dami/anaconda3/envs/fenics_d/lib/python3.10/site-packages/urllib3/util/retry.py", line 550, in increment
    raise six.reraise(type(error), error, _stacktrace)
  File "/home/dami/anaconda3/envs/fenics_d/lib/python3.10/site-packages/urllib3/packages/six.py", line 770, in reraise
    raise value
  File "/home/dami/anaconda3/envs/fenics_d/lib/python3.10/site-packages/urllib3/connectionpool.py", line 703, in urlopen
    httplib_response = self._make_request(
  File "/home/dami/anaconda3/envs/fenics_d/lib/python3.10/site-packages/urllib3/connectionpool.py", line 451, in _make_request
    self._raise_timeout(err=e, url=url, timeout_value=read_timeout)
  File "/home/dami/anaconda3/envs/fenics_d/lib/python3.10/site-packages/urllib3/connectionpool.py", line 340, in _raise_timeout
    raise ReadTimeoutError(
urllib3.exceptions.ReadTimeoutError: HTTPSConnectionPool(host='api.wandb.ai', port=443): Read timed out. (read timeout=10)

During handling of the above exception, another exception occurred:

Traceback (most recent call last):
  File "/home/dami/anaconda3/envs/fenics_d/lib/python3.10/site-packages/wandb/sdk/lib/retry.py", line 108, in __call__
    result = self._call_fn(*args, **kwargs)
  File "/home/dami/anaconda3/envs/fenics_d/lib/python3.10/site-packages/wandb/sdk/internal/internal_api.py", line 158, in execute
    return self.client.execute(*args, **kwargs)
  File "/home/dami/anaconda3/envs/fenics_d/lib/python3.10/site-packages/wandb/vendor/gql-0.2.0/wandb_gql/client.py", line 52, in execute
    result = self._get_result(document, *args, **kwargs)
  File "/home/dami/anaconda3/envs/fenics_d/lib/python3.10/site-packages/wandb/vendor/gql-0.2.0/wandb_gql/client.py", line 60, in _get_result
    return self.transport.execute(document, *args, **kwargs)
  File "/home/dami/anaconda3/envs/fenics_d/lib/python3.10/site-packages/wandb/vendor/gql-0.2.0/wandb_gql/transport/requests.py", line 38, in execute
    request = requests.post(self.url, **post_args)
  File "/home/dami/anaconda3/envs/fenics_d/lib/python3.10/site-packages/requests/api.py", line 115, in post
    return request("post", url, data=data, json=json, **kwargs)
  File "/home/dami/anaconda3/envs/fenics_d/lib/python3.10/site-packages/requests/api.py", line 59, in request
    return session.request(method=method, url=url, **kwargs)
  File "/home/dami/anaconda3/envs/fenics_d/lib/python3.10/site-packages/requests/sessions.py", line 587, in request
    resp = self.send(prep, **send_kwargs)
  File "/home/dami/anaconda3/envs/fenics_d/lib/python3.10/site-packages/requests/sessions.py", line 701, in send
    r = adapter.send(request, **kwargs)
  File "/home/dami/anaconda3/envs/fenics_d/lib/python3.10/site-packages/requests/adapters.py", line 578, in send
    raise ReadTimeout(e, request=request)
requests.exceptions.ReadTimeout: HTTPSConnectionPool(host='api.wandb.ai', port=443): Read timed out. (read timeout=10)
2022-07-21 20:27:30,356 INFO    MainThread:1816151 [internal.py:handle_exit():80] Internal process exited
